<mujoco model="k1_description">
  <compiler angle="radian"/>

  <asset>
    <mesh name="base_link" content_type="model/stl" file="base_link.STL"/>
    <mesh name="r1" content_type="model/stl" file="r1.STL"/>
    <mesh name="r2" content_type="model/stl" file="r2.STL"/>
    <mesh name="r3" content_type="model/stl" file="r3.STL"/>
    <mesh name="r4" content_type="model/stl" file="r4.STL"/>
    <mesh name="r5" content_type="model/stl" file="r5.STL"/>
    <mesh name="r6" content_type="model/stl" file="r6.STL"/>
    <mesh name="r7" content_type="model/stl" file="r7.STL"/>
    <mesh name="rt" content_type="model/stl" file="rt.STL"/>
    <mesh name="l1" content_type="model/stl" file="l1.STL"/>
    <mesh name="l2" content_type="model/stl" file="l2.STL"/>
    <mesh name="l3" content_type="model/stl" file="l3.STL"/>
    <mesh name="l4" content_type="model/stl" file="l4.STL"/>
    <mesh name="l5" content_type="model/stl" file="l5.STL"/>
    <mesh name="l6" content_type="model/stl" file="l6.STL"/>
    <mesh name="l7" content_type="model/stl" file="l7.STL"/>
    <mesh name="lt" content_type="model/stl" file="lt.STL"/>
  </asset>

  <worldbody>
    <geom type="mesh" rgba="0.898039 0.917647 0.929412 1" mesh="base_link"/>
    <body name="r1" pos="0 -0.015 0.217" quat="0.707105 0.707108 0 0">
      <inertial pos="2.46089e-06 2.84971e-07 0.164287" quat="0.707167 2.59119e-05 9.84412e-06 0.707047" mass="1.49079" diaginertia="0.00378376 0.00305952 0.00212532"/>
      <joint name="r-j1" pos="0 0 0" axis="0 0 1" range="-6.2832 6.2832"/>
      <geom type="mesh" rgba="0.898039 0.917647 0.929412 1" mesh="r1"/>
      <body name="r2" pos="0 0 0.2075" quat="-2.59734e-06 2.59735e-06 0.707108 -0.707105">
        <inertial pos="1.71094e-05 -0.0452986 -0.000762955" quat="0.727478 0.686131 0.000277485 0.000318842" mass="2.70256" diaginertia="0.00984923 0.00748401 0.00588084"/>
        <joint name="r-j2" pos="0 0 0" axis="0 0 1" range="-1.8325 1.8325"/>
        <geom type="mesh" rgba="0.898039 0.917647 0.929412 1" mesh="r2"/>
        <body name="r3" quat="0.707105 0.707108 0 0">
          <inertial pos="0.00699745 0.000445737 0.236701" quat="0.709376 0.00337082 0.00258928 0.704817" mass="3.54789" diaginertia="0.0186989 0.0185309 0.00375394"/>
          <joint name="r-j3" pos="0 0 0" axis="0 0 1" range="-6.2832 6.2832"/>
          <geom type="mesh" rgba="0.898039 0.917647 0.929412 1" mesh="r3"/>
          <body name="r4" pos="-0.00040027 0 0.33028" quat="0.707105 -0.707108 0 0">
            <inertial pos="0.00464519 -0.0316041 0.000428234" quat="0.711055 0.701258 0.0356952 0.0369292" mass="1.47374" diaginertia="0.00380982 0.00281145 0.00223921"/>
            <joint name="r-j4" pos="0 0 0" axis="0 0 1" range="-2.5307 0.5235"/>
            <geom type="mesh" rgba="0.898039 0.917647 0.929412 1" mesh="r4"/>
            <body name="r5" quat="0.707105 0.707108 0 0">
              <inertial pos="-2.73577e-06 0.00407884 0.18353" quat="0.706646 -0.037008 0.0369129 0.705634" mass="2.28081" diaginertia="0.00561892 0.0054924 0.00191859"/>
              <joint name="r-j5" pos="0 0 0" axis="0 0 1" range="-6.2832 6.2832"/>
              <geom type="mesh" rgba="0.898039 0.917647 0.929412 1" mesh="r5"/>
              <body name="r6" pos="0 0 0.23494" quat="-2.59734e-06 2.59735e-06 0.707108 -0.707105">
                <inertial pos="-1.87506e-07 -0.086963 0.00554801" quat="0.430647 0.56085 -0.560836 0.430644" mass="1.76168" diaginertia="0.00445732 0.00444042 0.00137145"/>
                <joint name="r-j6" pos="0 0 0" axis="0 0 1" range="-1.8325 1.8325"/>
                <geom type="mesh" rgba="0.898039 0.917647 0.929412 1" mesh="r6"/>
                <body name="r7" quat="0.707105 0.707108 0 0">
                  <inertial pos="2.68777e-07 -3.37424e-05 0.17628" quat="0.0010751 0.707106 0.0010751 0.707106" mass="0.636542" diaginertia="0.000512339 0.000371318 0.000370813"/>
                  <joint name="r-j7" pos="0 0 0" axis="0 0 1" range="-6.2832 6.2832"/>
                  <geom type="mesh" rgba="1 1 1 1" mesh="r7"/>
                  <geom pos="0 0 0.20277" quat="1 0 0 0" type="mesh" rgba="0.792157 0.819608 0.933333 1" mesh="rt"/>
                </body>
              </body>
            </body>
          </body>
        </body>
      </body>
    </body>
    <body name="l1" pos="0 0.015 0.217" quat="-2.59734e-06 -2.59735e-06 -0.707108 -0.707105">
      <inertial pos="-2.46089e-06 -2.84971e-07 0.164287" quat="0.707167 -2.59119e-05 -9.84412e-06 0.707047" mass="1.49079" diaginertia="0.00378376 0.00305952 0.00212532"/>
      <joint name="l-j1" pos="0 0 0" axis="0 0 1" range="-6.2832 6.2832"/>
      <geom type="mesh" rgba="0.898039 0.917647 0.929412 1" mesh="l1"/>
      <body name="l2" pos="0 0 0.2075" quat="0.707105 -0.707108 0 0">
        <inertial pos="1.71098e-05 -0.0452986 -0.000764631" quat="0.727478 0.686131 0.000277483 0.000318848" mass="2.70256" diaginertia="0.00984923 0.00748401 0.00588084"/>
        <joint name="l-j2" pos="0 0 0" axis="0 0 1" range="-1.8325 1.8325"/>
        <geom type="mesh" rgba="0.898039 0.917647 0.929412 1" mesh="l2"/>
        <body name="l3" quat="0.707105 0.707108 0 0">
          <inertial pos="0.00699745 0.000444598 0.236701" quat="0.709376 0.00337002 0.00259008 0.704817" mass="3.54789" diaginertia="0.0186989 0.0185309 0.00375394"/>
          <joint name="l-j3" pos="0 0 0" axis="0 0 1" range="-6.2832 6.2832"/>
          <geom type="mesh" rgba="0.898039 0.917647 0.929412 1" mesh="l3"/>
          <body name="l4" pos="-0.00040027 0 0.33028" quat="0.707105 -0.707108 0 0">
            <inertial pos="0.00464517 -0.0316039 0.000428109" quat="0.711056 0.701257 0.0356954 0.0369292" mass="1.47374" diaginertia="0.00380982 0.00281146 0.00223921"/>
            <joint name="l-j4" pos="0 0 0" axis="0 0 1" range="-2.5307 0.5235"/>
            <geom type="mesh" rgba="0.898039 0.917647 0.929412 1" mesh="l4"/>
            <body name="l5" quat="0.707105 0.707108 0 0">
              <inertial pos="2.28035e-06 -0.00407998 0.18353" quat="0.706533 0.037006 -0.0369278 0.705746" mass="2.28088" diaginertia="0.005619 0.00549252 0.00191867"/>
              <joint name="l-j5" pos="0 0 0" axis="0 0 1" range="-6.2832 6.2832"/>
              <geom type="mesh" rgba="0.898039 0.917647 0.929412 1" mesh="l5"/>
              <body name="l6" pos="0 0 0.23494" quat="0.707105 -0.707108 0 0">
                <inertial pos="-1.87506e-07 -0.086963 0.00555106" quat="0.430647 0.56085 -0.560836 0.430644" mass="1.76168" diaginertia="0.00445732 0.00444042 0.00137145"/>
                <joint name="l-j6" pos="0 0 0" axis="0 0 1" range="-1.8325 1.8325"/>
                <geom type="mesh" rgba="0.898039 0.917647 0.929412 1" mesh="l6"/>
                <body name="l7" quat="0.707105 0.707108 0 0">
                  <inertial pos="2.68777e-07 -3.10986e-05 0.17628" quat="0.00107456 0.707106 0.00107456 0.707106" mass="0.636542" diaginertia="0.000512339 0.000371319 0.000370813"/>
                  <joint name="l-j7" pos="0 0 0" axis="0 0 1" range="-6.2832 6.2832"/>
                  <geom type="mesh" rgba="1 1 1 1" mesh="l7"/>
                  <geom pos="0 0 0.202772" quat="1 0 0 0" type="mesh" rgba="0.792157 0.819608 0.933333 1" mesh="lt"/>
                </body>
              </body>
            </body>
          </body>
        </body>
      </body>
    </body>
  </worldbody>
</mujoco>
