<mujoco model="K1">
    <compiler angle="radian"/>
    <size njmax="500" nconmax="100" />
    <option timestep="0.001"/>
      
    <default>
    <default class="k1">
      <joint frictionloss="0.3" armature="0.005"/>
          <position  forcerange="-100 100"/>
      <!-- <position inheritrange="1" forcerange="-100 100"/> -->
      </default>

      <default class="visual">
        <geom group="2" type="mesh" contype="0" conaffinity="0" density="0"/>
      </default>
        
      <default class="collision">
        <geom group="3" type="capsule"/>
      </default>

      <default class="finger">
        <joint frictionloss="0" type="slide" damping="100"/>
        <position forcerange="-100 100"/>
      </default>


  </default>

  <asset>
    <texture name="grid" type="2d" builtin="checker" rgb1=".2 .3 .4" rgb2=".1 0.15 0.2" width="512" height="512" mark="cross" markrgb=".8 .8 .8"/>
    <material name="gridmat" texture="grid" texrepeat="10 10" reflectance="0.2"/>

    <texture type="skybox" builtin="gradient" rgb1="0.3 0.5 0.7" rgb2="0 0 0" width="512" height="3072"/>
    <texture type="2d" name="groundplane" builtin="checker" mark="edge" rgb1="0.2 0.3 0.4" rgb2="0.1 0.2 0.3" markrgb="0.8 0.8 0.8" width="300" height="300"/>
    <material name="groundplane" texture="groundplane" texuniform="true" texrepeat="5 5" reflectance="0.0"/>


    <mesh name="base_link" file="K1/meshes/base_link.STL"/>
    <mesh name="r1" file="K1/meshes/r1.STL"/>
    <mesh name="r2" file="K1/meshes/r2.STL"/>
    <mesh name="r3" file="K1/meshes/r3.STL"/>
    <mesh name="r4" file="K1/meshes/r4.STL"/>
    <mesh name="r5" file="K1/meshes/r5.STL"/>
    <mesh name="r6" file="K1/meshes/r6.STL"/>
    <mesh name="r7" file="K1/meshes/r7.STL"/>
    <mesh name="rt" file="K1/meshes/rt.STL"/>
    <mesh name="l1" file="K1/meshes/l1.STL"/>
    <mesh name="l2" file="K1/meshes/l2.STL"/>
    <mesh name="l3" file="K1/meshes/l3.STL"/>
    <mesh name="l4" file="K1/meshes/l4.STL"/>
    <mesh name="l5" file="K1/meshes/l5.STL"/>
    <mesh name="l6" file="K1/meshes/l6.STL"/>
    <mesh name="l7" file="K1/meshes/l7.STL"/>
    <mesh name="lt" file="K1/meshes/lt.STL"/>
    <mesh name="gripper_base_link" file="pgc50final/meshes/gripper_base_link.STL"/>
    <mesh name="finger1_link" file="pgc50final/meshes/finger1_link.STL"/>
    <mesh name="finger2_link" file="pgc50final/meshes/finger2_link.STL"/>
  </asset>

  <worldbody>
  <light pos="0 0 1.5" dir="0 0 -1" directional="true"/>
    <geom name="floor" size="0.0 0 0.000001" type="plane" pos="0 0 0.0" material="groundplane"/>
   
   <body name="K1" pos="0 0 0.3">
    <geom type="mesh" rgba="0.898039 0.917647 0.929412 1" mesh="base_link"/>
    <body name="r1" pos="0 -0.015 0.217" quat="0.707105 0.707108 0 0">
      <inertial pos="2.46089e-06 2.84971e-07 0.164287" quat="0.707167 2.59119e-05 9.84412e-06 0.707047" mass="1.49079" diaginertia="0.00378376 0.00305952 0.00212532"/>
      <joint name="r-j1" pos="0 0 0" axis="0 0 1" range="-6.2832 6.2832"/>
      <geom type="mesh" rgba="0.898039 0.917647 0.929412 1" mesh="r1"/>
      <body name="r2" pos="-0.00019729 0 0.2085" quat="-2.59665e-06 2.59805e-06 0.707298 -0.706916">
        <inertial pos="1.71094e-05 -0.0452986 -0.000762955" quat="0.727478 0.686131 0.000277485 0.000318842" mass="2.70256" diaginertia="0.00984923 0.00748401 0.00588084"/>
        <joint name="r-j2" pos="0 0 0" axis="0 0 1" range="-1.8325 1.8325"/>
        <geom type="mesh" rgba="0.898039 0.917647 0.929412 1" mesh="r2"/>
        <body name="r3" pos="0.00047133 0 -0.00013467" quat="0.707644 0.706569 0 0">
          <inertial pos="0.00699745 0.000445737 0.236701" quat="0.709376 0.00337082 0.00258928 0.704817" mass="3.54789" diaginertia="0.0186989 0.0185309 0.00375394"/>
          <joint name="r-j3" pos="0 0 0" axis="0 0 1" range="-6.2832 6.2832"/>
          <geom type="mesh" rgba="0.898039 0.917647 0.929412 1" mesh="r3"/>
          <body name="r4" pos="-0.0002583 0 0.328521" quat="0.706663 -0.70755 0 0">
            <inertial pos="0.00464519 -0.0316041 0.000428234" quat="0.711055 0.701258 0.0356952 0.0369292" mass="1.47374" diaginertia="0.00380982 0.00281145 0.00223921"/>
            <joint name="r-j4" pos="0 0 0" axis="0 0 1" range="-2.5307 0.5235"/>
            <geom type="mesh" rgba="0.898039 0.917647 0.929412 1" mesh="r4"/>
            <body name="r5" pos="0.00012406 0 -0.00054639" quat="0.706969 0.707245 0 0">
              <inertial pos="-2.73577e-06 0.00407884 0.18353" quat="0.706646 -0.037008 0.0369129 0.705634" mass="2.28081" diaginertia="0.00561892 0.0054924 0.00191859"/>
              <joint name="r-j5" pos="0 0 0" axis="0 0 1" range="-6.2832 6.2832"/>
              <geom type="mesh" rgba="0.898039 0.917647 0.929412 1" mesh="r5"/>
              <body name="r6" pos="7.249e-05 0 0.232096" quat="-2.59857e-06 2.59612e-06 0.706773 -0.70744">
                <inertial pos="-1.87506e-07 -0.086963 0.00554801" quat="0.430647 0.56085 -0.560836 0.430644" mass="1.76168" diaginertia="0.00445732 0.00444042 0.00137145"/>
                <joint name="r-j6" pos="0 0 0" axis="0 0 1" range="-1.8325 1.8325"/>
                <geom type="mesh" rgba="0.898039 0.917647 0.929412 1" mesh="r6"/>
                <body name="r7" pos="-0.00010786 0 -0.00053603" quat="0.707823 0.70639 0 0">
                  <inertial pos="5.30203e-07 -3.01917e-05 0.200554" quat="1 3.10661e-05 6.16966e-06 -3.33979e-05" mass="0.998702" diaginertia="0.00157236 0.00155176 0.000672908"/>
                  <joint name="r-j7" pos="0 0 0" axis="0 0 1" range="-6.2832 6.2832"/>
                  <geom type="mesh" rgba="1 1 1 1" mesh="r7"/>
                  <geom pos="0 0 0.203341" quat="1 0 0 0" type="mesh" rgba="0.792157 0.819608 0.933333 1" mesh="rt"/>
                 
                  <body name="r_gripper_base" pos="0 0 0.203341" quat="1 0 0 0">
                    <body name="r_gripper_base2" pos="0 0 0" quat="0.707105 0 0 0.707108">
                      <geom type="mesh" rgba="0.69804 0.69804 0.69804 1" mesh="gripper_base_link"/>
                      <body name="right_finger1" pos="-0.025038 0.010849 0.099">
                        <inertial pos="0.0068518 -0.0045468 -0.0031193" quat="0.674942 -0.0950085 -0.303278 0.66592" mass="0.065952" diaginertia="6.24665e-06 4.49395e-06 4.0436e-06"/>
                        <joint name="right_finger1_joint" pos="0 0 0" axis="1 0 0" type="slide" range="0 0.0185" actuatorfrcrange="-50 50" frictionloss="5"/>
                        <geom type="mesh" rgba="0.69804 0.69804 0.69804 1" mesh="finger1_link"/>
                      </body>
                      <body name="right_finger2" pos="0.025047 -0.010851 0.099">
                        <inertial pos="-0.0068518 0.0045468 -0.0031193" quat="0.674942 0.0950085 0.303278 0.66592" mass="0.065952" diaginertia="6.24665e-06 4.49395e-06 4.0436e-06"/>
                        <joint name="right_finger2_joint" pos="0 0 0" axis="1 0 0" type="slide" actuatorfrcrange="-50 50" frictionloss="5"/>
                        <geom type="mesh" rgba="0.69804 0.69804 0.69804 1" mesh="finger2_link"/>
                      </body>
                    </body>
                  </body>
                </body>
              </body>
            </body>
          </body>
        </body>
      </body>
    </body>
    <body name="l1" pos="0 0.015 0.217" quat="-2.59734e-06 -2.59735e-06 -0.707108 -0.707105">
      <inertial pos="-2.46089e-06 -2.84971e-07 0.164287" quat="0.707167 -2.59119e-05 -9.84412e-06 0.707047" mass="1.49079" diaginertia="0.00378376 0.00305952 0.00212532"/>
      <joint name="l-j1" pos="0 0 0" axis="0 0 1" range="-6.2832 6.2832"/>
      <geom type="mesh" rgba="0.898039 0.917647 0.929412 1" mesh="l1"/>
      <body name="l2" pos="-2.649e-05 0 0.209222" quat="0.706804 -0.707409 0 0">
        <inertial pos="1.71098e-05 -0.0452986 -0.000764631" quat="0.727478 0.686131 0.000277483 0.000318848" mass="2.70256" diaginertia="0.00984923 0.00748401 0.00588084"/>
        <joint name="l-j2" pos="0 0 0" axis="0 0 1" range="-1.8325 1.8325"/>
        <geom type="mesh" rgba="0.898039 0.917647 0.929412 1" mesh="l2"/>
        <body name="l3" pos="0.00027772 0 -7.083e-05" quat="0.707509 0.706704 0 0">
          <inertial pos="0.00699745 0.000444598 0.236701" quat="0.709376 0.00337002 0.00259008 0.704817" mass="3.54789" diaginertia="0.0186989 0.0185309 0.00375394"/>
          <joint name="l-j3" pos="0 0 0" axis="0 0 1" range="-6.2832 6.2832"/>
          <geom type="mesh" rgba="0.898039 0.917647 0.929412 1" mesh="l3"/>
          <body name="l4" pos="7.1e-05 0 0.328727" quat="0.707798 -0.706414 0 0">
            <inertial pos="0.00464517 -0.0316039 0.000428109" quat="0.711056 0.701257 0.0356954 0.0369292" mass="1.47374" diaginertia="0.00380982 0.00281146 0.00223921"/>
            <joint name="l-j4" pos="0 0 0" axis="0 0 1" range="-2.5307 0.5235"/>
            <geom type="mesh" rgba="0.898039 0.917647 0.929412 1" mesh="l4"/>
            <body name="l5" pos="0.00018186 0 0.00028147" quat="0.706954 0.707259 0 0">
              <inertial pos="2.28035e-06 -0.00407998 0.18353" quat="0.706533 0.037006 -0.0369278 0.705746" mass="2.28088" diaginertia="0.005619 0.00549252 0.00191867"/>
              <joint name="l-j5" pos="0 0 0" axis="0 0 1" range="-6.2832 6.2832"/>
              <geom type="mesh" rgba="0.898039 0.917647 0.929412 1" mesh="l5"/>
              <body name="l6" pos="0.00012651 0 0.232208" quat="0.706925 -0.707289 0 0">
                <inertial pos="-1.87506e-07 -0.086963 0.00555106" quat="0.430647 0.56085 -0.560836 0.430644" mass="1.76168" diaginertia="0.00445732 0.00444042 0.00137145"/>
                <joint name="l-j6" pos="0 0 0" axis="0 0 1" range="-1.8325 1.8325"/>
                <geom type="mesh" rgba="0.898039 0.917647 0.929412 1" mesh="l6"/>
                <body name="l7" pos="0.00022313 0 -0.00033076" quat="0.708809 0.7054 0 0">
                  <inertial pos="5.30203e-07 -2.85067e-05 0.200487" quat="1 5.47195e-05 6.19269e-06 -3.33997e-05" mass="0.998702" diaginertia="0.00156663 0.00154603 0.000672908"/>
                  <joint name="l-j7" pos="0 0 0" axis="0 0 1" range="-6.2832 6.2832"/>
                  <geom type="mesh" rgba="1 1 1 1" mesh="l7"/>
                  <geom pos="0 0 0.203155" quat="1 0 0 0" type="mesh" rgba="0.792157 0.819608 0.933333 1" mesh="lt"/>
                  
                  <body name="l_gripper_base" pos="0 0 0.203155" quat="1 0 0 0">
                    <body name="l_gripper_base2" pos="0 0 0" quat="0.707105 0 0 0.707108">
                      <geom type="mesh" rgba="0.69804 0.69804 0.69804 1" mesh="gripper_base_link"/>
                      <body name="left_finger1" pos="-0.025038 0.010849 0.099">
                        <inertial pos="0.0068518 -0.0045468 -0.0031193" quat="0.674942 -0.0950085 -0.303278 0.66592" mass="0.065952" diaginertia="6.24665e-06 4.49395e-06 4.0436e-06"/>
                        <joint name="left_finger1_joint" pos="0 0 0" axis="1 0 0" type="slide" range="0 0.0185" actuatorfrcrange="-50 50" frictionloss="5"/>
                        <geom type="mesh" rgba="0.69804 0.69804 0.69804 1" mesh="finger1_link"/>
                      </body>
                      <body name="left_finger2" pos="0.025047 -0.010851 0.099">
                        <inertial pos="-0.0068518 0.0045468 -0.0031193" quat="0.674942 0.0950085 0.303278 0.66592" mass="0.065952" diaginertia="6.24665e-06 4.49395e-06 4.0436e-06"/>
                        <joint name="left_finger2_joint" pos="0 0 0" axis="1 0 0" type="slide" actuatorfrcrange="-50 50" frictionloss="5"/>
                        <geom type="mesh" rgba="0.69804 0.69804 0.69804 1" mesh="finger2_link"/>
                    </body>
                  </body>
                </body>
                </body>
              </body>
            </body>
          </body>
        </body>
      </body>
    </body>
     </body>
  </worldbody>


  <contact>
    <exclude body1="r1" body2="r2"/>
    <exclude body1="r2" body2="r3"/>
    <exclude body1="r3" body2="r4"/>
    <exclude body1="r4" body2="r5"/>
    <exclude body1="r5" body2="r6"/>
    <exclude body1="r6" body2="r7"/>

    <exclude body1="l1" body2="l2"/>
    <exclude body1="l2" body2="l3"/>
    <exclude body1="l3" body2="l4"/>
    <exclude body1="l4" body2="l5"/>
    <exclude body1="l5" body2="l6"/>
    <exclude body1="l6" body2="l7"/>

    <exclude body1="K1" body2="r1"/>
    <exclude body1="K1" body2="l1"/>
  </contact>

    <!-- <equality>
        <joint name="r_gripper_sync" joint1="right_finger1_joint" joint2="right_finger2_joint" polycoef="0 -1 0" solimp="0.95 0.99 0.001" solref="0.005 1"/>

        <joint name="l_gripper_sync" joint1="left_finger1_joint" joint2="left_finger2_joint" polycoef="0 -1 0" solimp="0.95 0.99 0.001" solref="0.005 1"/>
    </equality>
     -->
    <actuator>
        <!-- Right Arm Actuators -->
        <position name="r-j1" joint="r-j1" ctrllimited="true" ctrlrange="-6.2832 6.2832" class="k1" kp="40" kv="5"/>
        <position name="r-j2" joint="r-j2" ctrllimited="true" ctrlrange="-1.8325 1.8325" class="k1" kp="40" kv="5"/>
        <position name="r-j3" joint="r-j3" ctrllimited="true" ctrlrange="-6.2832 6.2832" class="k1" kp="30" kv="5"/>
        <position name="r-j4" joint="r-j4" ctrllimited="true" ctrlrange="-2.5307 0.5235" class="k1" kp="40" kv="5"/>
        <position name="r-j5" joint="r-j5" ctrllimited="true" ctrlrange="-6.2832 6.2832" class="k1" kp="5" kv="1.5"/>
        <position name="r-j6" joint="r-j6" ctrllimited="true" ctrlrange="-1.8325 1.8325" class="k1" kp="5" kv="1.5"/>
        <position name="r-j7" joint="r-j7" ctrllimited="true" ctrlrange="-6.2832 6.2832" class="k1" kp="5" kv="1.5"/>
        
        <!-- Left Arm Actuators -->
        <position name="l-j1" joint="l-j1" ctrllimited="true" ctrlrange="-6.2832 6.2832" class="k1" kp="40" kv="5"/>
        <position name="l-j2" joint="l-j2" ctrllimited="true" ctrlrange="-1.8325 1.8325" class="k1" kp="40" kv="5"/>
        <position name="l-j3" joint="l-j3" ctrllimited="true" ctrlrange="-6.2832 6.2832" class="k1" kp="30" kv="5"/>
        <position name="l-j4" joint="l-j4" ctrllimited="true" ctrlrange="-2.5307 0.5235" class="k1" kp="40" kv="5"/>
        <position name="l-j5" joint="l-j5" ctrllimited="true" ctrlrange="-6.2832 6.2832" class="k1" kp="5" kv="1.5"/>
        <position name="l-j6" joint="l-j6" ctrllimited="true" ctrlrange="-1.8325 1.8325" class="k1" kp="5" kv="1.5"/>
        <position name="l-j7" joint="l-j7" ctrllimited="true" ctrlrange="-6.2832 6.2832" class="k1" kp="5" kv="1.5"/>

        <!-- <position name="r_gripper" joint="right_finger1_joint" ctrllimited="true" ctrlrange="0 0.01875" kp="10000" kv="100"/>
        <position name="l_gripper" joint="left_finger1_joint" ctrllimited="true" ctrlrange="0 0.01875" kp="10000" kv="100"/> -->

        <position name="r_gripper_1" joint="right_finger1_joint" class="finger" ctrllimited="true" ctrlrange="0 0.01875" kp="400" kv="5" />
        <position name="r_gripper_2" joint="right_finger2_joint" class="finger" ctrllimited="true" ctrlrange="-0.01875 0 " kp="400" kv="5" />
        
        <position name="l_gripper_1" joint="left_finger1_joint" class="finger" ctrllimited="true" ctrlrange="0 0.01875" kp="400" kv="5" />
        <position name="l_gripper_2" joint="left_finger2_joint" class="finger" ctrllimited="true" ctrlrange="-0.01875 0 " kp="400" kv="5" />
    </actuator>
</mujoco>
